[2024-08-10T11:15:12.897+0300] {local_task_job_runner.py:120} INFO - ::group::Pre task execution logs
[2024-08-10T11:15:12.922+0300] {taskinstance.py:2076} INFO - Dependencies all met for dep_context=non-requeueable deps ti=<TaskInstance: pollution_air_dags.extract_air_pollution scheduled__2024-08-09T00:00:00+00:00 [queued]>
[2024-08-10T11:15:12.934+0300] {taskinstance.py:2076} INFO - Dependencies all met for dep_context=requeueable deps ti=<TaskInstance: pollution_air_dags.extract_air_pollution scheduled__2024-08-09T00:00:00+00:00 [queued]>
[2024-08-10T11:15:12.934+0300] {taskinstance.py:2306} INFO - Starting attempt 1 of 2
[2024-08-10T11:15:12.980+0300] {taskinstance.py:2330} INFO - Executing <Task(PythonOperator): extract_air_pollution> on 2024-08-09 00:00:00+00:00
[2024-08-10T11:15:12.992+0300] {standard_task_runner.py:64} INFO - Started process 934 to run task
[2024-08-10T11:15:13.000+0300] {standard_task_runner.py:90} INFO - Running: ['airflow', 'tasks', 'run', 'pollution_air_dags', 'extract_air_pollution', 'scheduled__2024-08-09T00:00:00+00:00', '--job-id', '93', '--raw', '--subdir', 'DAGS_FOLDER/air_pollution_dags.py', '--cfg-path', '/tmp/tmpqjdg50cq']
[2024-08-10T11:15:13.005+0300] {standard_task_runner.py:91} INFO - Job 93: Subtask extract_air_pollution
[2024-08-10T11:15:13.081+0300] {task_command.py:426} INFO - Running <TaskInstance: pollution_air_dags.extract_air_pollution scheduled__2024-08-09T00:00:00+00:00 [running]> on host DESKTOP-DKUGVOH.
[2024-08-10T11:15:13.222+0300] {taskinstance.py:2648} INFO - Exporting env vars: AIRFLOW_CTX_DAG_OWNER='airflow' AIRFLOW_CTX_DAG_ID='pollution_air_dags' AIRFLOW_CTX_TASK_ID='extract_air_pollution' AIRFLOW_CTX_EXECUTION_DATE='2024-08-09T00:00:00+00:00' AIRFLOW_CTX_TRY_NUMBER='1' AIRFLOW_CTX_DAG_RUN_ID='scheduled__2024-08-09T00:00:00+00:00'
[2024-08-10T11:15:13.226+0300] {taskinstance.py:430} INFO - ::endgroup::
[2024-08-10T11:15:13.227+0300] {taskinstance.py:441} INFO - ::group::Post task execution logs
[2024-08-10T11:15:13.228+0300] {taskinstance.py:2905} ERROR - Task failed with exception
Traceback (most recent call last):
  File "/home/florentino/.local/lib/python3.10/site-packages/airflow/models/taskinstance.py", line 465, in _execute_task
    result = _execute_callable(context=context, **execute_callable_kwargs)
  File "/home/florentino/.local/lib/python3.10/site-packages/airflow/models/taskinstance.py", line 432, in _execute_callable
    return execute_callable(context=context, **execute_callable_kwargs)
  File "/home/florentino/.local/lib/python3.10/site-packages/airflow/models/baseoperator.py", line 401, in wrapper
    return func(self, *args, **kwargs)
  File "/home/florentino/.local/lib/python3.10/site-packages/airflow/operators/python.py", line 235, in execute
    return_value = self.execute_callable()
  File "/home/florentino/.local/lib/python3.10/site-packages/airflow/operators/python.py", line 252, in execute_callable
    return self.python_callable(*self.op_args, **self.op_kwargs)
  File "/home/florentino/airflow/dags/extract_air_pollution.py", line 5, in extract_air_pollution
    with open('air_pollution_data.csv', mode='r') as file:
FileNotFoundError: [Errno 2] No such file or directory: 'air_pollution_data.csv'
[2024-08-10T11:15:13.262+0300] {taskinstance.py:1206} INFO - Marking task as UP_FOR_RETRY. dag_id=pollution_air_dags, task_id=extract_air_pollution, run_id=scheduled__2024-08-09T00:00:00+00:00, execution_date=20240809T000000, start_date=20240810T081512, end_date=20240810T081513
[2024-08-10T11:15:13.310+0300] {standard_task_runner.py:110} ERROR - Failed to execute job 93 for task extract_air_pollution ([Errno 2] No such file or directory: 'air_pollution_data.csv'; 934)
[2024-08-10T11:15:13.337+0300] {local_task_job_runner.py:243} INFO - Task exited with return code 1
[2024-08-10T11:15:13.383+0300] {taskinstance.py:3503} INFO - 0 downstream tasks scheduled from follow-on schedule check
[2024-08-10T11:15:13.384+0300] {local_task_job_runner.py:222} INFO - ::endgroup::
